Workbook

Sheet README
A1: PinHunt set-first catalogue workbook
A2: Status: every seeded row is a RESEARCH CANDIDATE from public sources. Nothing here is verified or imported.
A3: Sets: one row per pin set / release (the unit we discover, check and approve). Formulas compute missing pins and completeness.
A4: Set_Members: one row per known pin slot in a set (found by research or from an official checklist). Missing slots can be added as rows with status 'missing'.
A5: Evidence: one row per source per set (official / news / fan; how it was accessed). Fan databases are discovery signals only.
A6: Coverage: release year x line counts, driven by formulas over Sets.
A7: Lookups: allowed values (drop-downs).
A8: Workflow: discovered -> evidenced (2+ independent sources or official) -> checked (person on official page / own photo) -> approved -> imported.
A9: Seed source: research/catalogue-engine/out/consolidated/staging_payload.json (404 sets, 871 pins).

Sheet Sets
A1: set_id | B1: set_name | C1: line / origin | D1: issuer | E1: release_date | F1: release_year | G1: family / programme | H1: sub_series | I1: format | J1: pins_per_pack | K1: has_chaser | L1: edition_type | M1: edition_size | N1: price | O1: currency | P1: product_code | Q1: expected_pins | R1: pins_found | S1: missing_pins | T1: completeness | U1: characters_found | V1: missing_characters (known) | W1: status | X1: confidence | Y1: primary_source_url | Z1: primary_source_class | AA1: second_source_url | AB1: independent_publishers | AC1: pinhunt_ids | AD1: reviewer | AE1: reviewed_at | AF1: notes | AG1: research_key
A2: PHS-0001 | B2: Disney Animated Cuties Mystery Pin Blind Pack – 2-Pc. | C2: Animated Cuties | D2: Disney Store | E2: 2026-01 | F2: 2026 | I2: mystery blind box, 2 random pins | J2: 2 | L2: open edition | N2: 22.99 | O2: USD | P2: US: 438030741301 | Asia/EU: 438030755384 | Q2: 8 | R2: 8 | S2: =IF(Q2="","",MAX(Q2-R2,0)) | T2: =IF(Q2="","",MIN(R2/Q2,1)) | U2: Aladdin; Alice; Esmeralda; Esmerelda; Jim Hawkins; Megara; Peter Pan; Pinocchio; Tinker Bell | W2: evidenced | X2: Medium | Y2: https://www.disneystore.asia/my/disney-animated-cuties-mystery-2-piece-pin-blind-pack-438030755384.html | Z2: official | AA2: https://www.disneystore.com/disney-animated-cuties-mystery-pin-blind-pack-2-pc.-438030741301.html | AB2: 8 | AG2: animated-cuties/series-1
A3: PHS-0002 | B3: Animated Cuties Series 2 Mystery Pin Set | C3: Animated Cuties | E3: 2026-10 | F3: 2026 | H3: Series 2 | J3: 2 | L3: open edition | N3: 22.99 | O3: USD | Q3: 8 | R3: 8 | S3: =IF(Q3="","",MAX(Q3-R3,0)) | T3: =IF(Q3="","",MIN(R3/Q3,1)) | U3: Ariel; Flynn Rider; Hercules; Kuzco; Li Shang; Maleficent; Sally; Vanellope | W3: evidenced | X3: Low | Y3: https://disneypinsblog.com/blogs/news/animated-cuties-series-2-mystery-pin-set-at-disney-parks | Z3: secondary | AA3: https://www.threads.com/@disneypinsblog/post/DeS8m9FjKzi/new-animated-cuties-series-mystery-pin-set-at-disney-parks-open-edition-and-the/ | AB3: 2 | AG3: animated-cuties/series-2
A4: PHS-0003 | B4: limited edition | C4: Brush Of Magic | H4: Limited Edition singles | I4: pin-on-pin: full-colour cloisonne top layer over laser-printed sketch on 'pegged animation paper', 3D Mickey glove with brushes | L4: limited edition | N4: 24.99 | O4: USD | R4: 18 | S4: =IF(Q4="","",MAX(Q4-R4,0)) | T4: =IF(Q4="","",MIN(R4/Q4,1)) | U4: Aladdin; Ariel; Bambi; Belle; Captain Hook; Cinderella; Darkwing Duck; Donald Duck; Dumbo; Gadget Hackwrench; Genie; Grumpy; Hades; Hercules; Maleficent; Marie; Mickey Mouse; Sorcerer Mickey | W4: evidenced (held) | X4: Unverified | Y4: https://www.disneystore.asia/hercules-limited-edition-pin-brush-of-magic-438010541600.html | Z4: official | AA4: https://www.disneystore.asia/maleficent-limited-edition-pin-sleeping-beauty-brush-of-magic-438010541112.html | AB4: 15 | AG4: brush-of-magic/limited-edition
A5: PHS-0004 | B5: Disney Brush of Magic Limited Release Mystery Pin Set | C5: Brush Of Magic | E5: 2026-03-03 | F5: 2026 | J5: 2 | L5: limited release | N5: 34.99 | O5: US: USD | UK: GBP | P5: US: 438010101590 | AU/UK: 438030648549 | Q5: 10 | R5: 10 | S5: =IF(Q5="","",MAX(Q5-R5,0)) | T5: =IF(Q5="","",MIN(R5/Q5,1)) | U5: Cheshire Cat; Dopey; Goofy; Oswald; Peter Pan; Pluto; Stitch; Tod; Todd; Ursula; Winnie; Winnie the Pooh | W5: evidenced (held) | X5: Medium | Y5: https://www.disneystore.co.uk/disney-brush-of-magic-limited-release-mystery-pin-set-438030648549.html | Z5: official | AA5: https://www.disneystore.com.au/disney-brush-of-magic-2-piece-mystery-pin-blind-pack-series-1-438030648549.html | AB5: 5 | AG5: brush-of-magic/mystery-series-1
A6: PHS-0005 | B6: Disney Brush of Magic Mystery Pin Blind Pack Series 2 - 2-Pc. - Limited Release | C6: Brush Of Magic | E6: 2026-06-16 | F6: 2026 | J6: 2 | L6: limited release | N6: 34.99 | O6: USD | P6: 438010243900 | Q6: 10 | R6: 10 | S6: =IF(Q6="","",MAX(Q6-R6,0)) | T6: =IF(Q6="","",MIN(R6/Q6,1)) | U6: Baloo; Chip; Dale; Jafar; Minnie Mouse; Pascal; Pegasus; Pinocchio; Pongo; Simba; Tigger | W6: evidenced (held) | X6: Low | Y6: https://disneypinsblog.com/brush-of-magic-series-2-mystery-pin-set-at-disney-store/ | Z6: secondary | AA6: https://www.dismerchandise.com/2026/06/16/disney-brush-of-magic-mystery-pin-blind-pack-series-2-2-pc-limited-release/ | AB6: 4 | AG6: brush-of-magic/mystery-series-2
A7: PHS-0006 | B7: Disney Brush of Magic Series 3 Limited Release Mystery Pin Set | C7: Brush Of Magic | E7: 2026-09-01 | F7: 2026 | J7: 2 | L7: limited release | N7: 34.99 | O7: US: USD | UK: GBP | P7: US: 438010809137 | Asia/UK: 438011184943 | Q7: 10 | R7: 10 | S7: =IF(Q7="","",MAX(Q7-R7,0)) | T7: =IF(Q7="","",MIN(R7/Q7,1)) | U7: Chernabog; Cruella de Vil; Daisy Duck; Dodger; Gaston; Louis; Megara; Mr. Toad; Powerline; Zazu | W7: evidenced | X7: Medium | Y7: https://www.disneystore.asia/my/disney-brush-of-magic-series-3-limited-release-mystery-pin-set-438011184943.html | Z7: official | AA7: https://www.disneystore.co.uk/disney-brush-of-magic-series-3-limited-release-mystery-pin-set-438011184943.html | AB7: 5 | AG7: brush-of-magic/mystery-series-3
A8: PHS-0007 | B8: Disney Classics London Pin Set | C8: Disney Classics London | D8: Disney Store | G8: Disney Classics | H8: London | I8: boxed/carded multi-pin set (non-mystery) | J8: 3 | N8: 20 | O8: GBP | P8: 438030541031 | Q8: 3 | R8: 3 | S8: =IF(Q8="","",MAX(Q8-R8,0)) | T8: =IF(Q8="","",MIN(R8/Q8,1)) | U8: Peter Pan; Stitch; Winnie the Pooh | W8: evidenced | X8: Medium | Y8: https://www.disneystore.co.uk/disney-classics-london-pin-set-438030541031.html | Z8: official | AB8: 1 | AG8: disney-classics-london/pin-set
A9: PHS-0008 | B9: Alice in Wonderland pins (March 2024) | C9: Disneyland Paris | E9: 2024-03-09 | F9: 2024 | R9: 4 | S9: =IF(Q9="","",MAX(Q9-R9,0)) | T9: =IF(Q9="","",MIN(R9/Q9,1)) | U9: Alice; Cheshire Cat; Mad Hatter; March Hare; White Rabbit | W9: evidenced | X9: Low | Y9: https://www.laughingplace.com/w/disney-parks/disneyland-paris-march-2024-pin-release-schedule/ | Z9: secondary | AA9: https://www.mousesteps.com/2024/02/28/disneyland-paris-march-2024-pin-release-schedule-revealed-including-stitch-and-tinker-bell-pins/ | AB9: 2 | AG9: dlp/2024/alice-in-wonderland-march-2024
A10: PHS-0009 | B10: Tinker Bell and Periwinkle jumbo LE (Symphony of Colours) | C10: Disneyland Paris | E10: 2024-03-23 | F10: 2024 | I10: jumbo | L10: limited edition | R10: 1 | S10: =IF(Q10="","",MAX(Q10-R10,0)) | T10: =IF(Q10="","",MIN(R10/Q10,1)) | U10: Periwinkle; Tinker Bell | W10: evidenced | X10: Low | Y10: https://www.laughingplace.com/w/disney-parks/disneyland-paris-march-2024-pin-release-schedule/ | Z10: secondary | AA10: https://www.mousesteps.com/2024/02/28/disneyland-paris-march-2024-pin-release-schedule-revealed-including-stitch-and-tinker-bell-pins/ | AB10: 2 | AG10: dlp/2024/tinker-bell-periwinkle-symphony-of-colours-jumbo
A11: PHS-0010 | B11: Flora, Fauna and Merryweather - Disneyland Paris birthday (April 12) | C11: Disneyland Paris | E11: 2024-04-12 | F11: 2024 | L11: limited edition | M11: 700 | Q11: 3 | R11: 3 | S11: =IF(Q11="","",MAX(Q11-R11,0)) | T11: =IF(Q11="","",MIN(R11/Q11,1)) | U11: Fauna; Flora; Merryweather | W11: evidenced | X11: Low | Y11: https://www.laughingplace.com/w/disney-parks/disneyland-paris-april-2024-pin-release-schedule/ | Z11: secondary | AA11: https://www.mousesteps.com/2024/03/27/disneyland-paris-releases-pin-trading-schedule-for-april-2024/ | AB11: 2 | AG11: dlp/2024/dlp-birthday-good-fairies-april-2024
A12: PHS-0011 | B12: Alice in Wonderland 2024 Pin Trading Event pins | C12: Disneyland Paris | E12: 2024-05-25 | F12: 2024 | I12: ticketed pin trading event release | R12: 5 | S12: =IF(Q12="","",MAX(Q12-R12,0)) | T12: =IF(Q12="","",MIN(R12/Q12,1)) | U12: Alice; Cheshire Cat; Mad Hatter; March Hare; Red Queen | W12: evidenced (held) | X12: Low | Y12: https://disneypinsblog.com/alice-in-wonderland-2024-pin-trading-event-at-disneyland-paris/ | Z12: secondary | AA12: https://www.mousesteps.com/2024/04/22/disneyland-paris-reveals-alice-in-wonderland-pins-for-pin-trading-event-on-may-25th-2024/ | AB12: 3 | AG12: dlp/2024/alice-in-wonderland-pin-trading-event-2024
A13: PHS-0012 | B13: Inside Out 2 pins | C13: Disneyland Paris | E13: 2024-06 | F13: 2024 | Q13: 4 | R13: 4 | S13: =IF(Q13="","",MAX(Q13-R13,0)) | T13: =IF(Q13="","",MIN(R13/Q13,1)) | U13: Anger; Ennui; Disgust; Envy; Fear; Embarrassment; Sadness; Anxiety; Joy | W13: evidenced | X13: Low | Y13: https://www.mousesteps.com/2024/05/27/disneyland-paris-pins-for-june-2024-revealed-including-disney-pride-and-inside-out-2/ | Z13: secondary | AA13: https://x.com/DLPReport/status/1795011556213772440 | AB13: 2 | AG13: dlp/2024/inside-out-2-june-2024
A14: PHS-0013 | B14: Toy Story Aliens pins | C14: Disneyland Paris | E14: 2024-06-08 | F14: 2024 | R14: 6 | S14: =IF(Q14="","",MAX(Q14-R14,0)) | T14: =IF(Q14="","",MIN(R14/Q14,1)) | U14: Alien; Buzz Lightyear; Carl Fredricksen; Russell; Edna Mode; Mr. Incredible; Anger; Sadness; Boo; Sulley; Jessie; Woody | W14: evidenced | X14: Low | Y14: https://www.mousesteps.com/2024/05/27/disneyland-paris-pins-for-june-2024-revealed-including-disney-pride-and-inside-out-2/ | Z14: secondary | AA14: https://x.com/DLPReport/status/1795011556213772440 | AB14: 2 | AG14: dlp/2024/toy-story-aliens-june-2024
A15: PHS-0014 | B15: Disney Princess pins (June 2024) | C15: Disneyland Paris | E15: 2024-06-15 | F15: 2024 | R15: 5 | S15: =IF(Q15="","",MAX(Q15-R15,0)) | T15: =IF(Q15="","",MIN(R15/Q15,1)) | U15: Aurora; Cinderella; Jasmine; Pocahontas; Snow White | W15: evidenced | X15: Low | Y15: https://www.mousesteps.com/2024/05/27/disneyland-paris-pins-for-june-2024-revealed-including-disney-pride-and-inside-out-2/ | Z15: secondary | AB15: 1 | AG15: dlp/2024/disney-princess-june-2024
A16: PHS-0015 | B16: Father's Day 2024 pin (Judy and Stu Hopps) | C16: Disneyland Paris | E16: 2024-06-16 | F16: 2024 | L16: limited edition | M16: 700 | Q16: 1 | R16: 1 | S16: =IF(Q16="","",MAX(Q16-R16,0)) | T16: =IF(Q16="","",MIN(R16/Q16,1)) | U16: Judy Hopps; Stu Hopps | W16: evidenced | X16: Low | Y16: https://www.mousesteps.com/2024/05/27/disneyland-paris-pins-for-june-2024-revealed-including-disney-pride-and-inside-out-2/ | Z16: secondary | AB16: 1 | AG16: dlp/2024/fathers-day-2024-judy-stu-hopps
A17: PHS-0016 | B17: Tinker Bell and King of Hearts pins (June 22) | C17: Disneyland Paris | E17: 2024-06-22 | F17: 2024 | R17: 2 | S17: =IF(Q17="","",MAX(Q17-R17,0)) | T17: =IF(Q17="","",MIN(R17/Q17,1)) | U17: King of Hearts; Tinker Bell | W17: evidenced | X17: Low | Y17: https://www.mousesteps.com/2024/05/27/disneyland-paris-pins-for-june-2024-revealed-including-disney-pride-and-inside-out-2/ | Z17: secondary | AB17: 1 | AG17: dlp/2024/tinker-bell-king-of-hearts-june-2024
A18: PHS-0017 | B18: 2024 summer sports merchandise - Mickey gold medal pin | C18: Disneyland Paris | E18: 2024-07 | F18: 2024 | Q18: 1 | R18: 1 | S18: =IF(Q18="","",MAX(Q18-R18,0)) | T18: =IF(Q18="","",MIN(R18/Q18,1)) | U18: Mickey Mouse | W18: evidenced | X18: Low | Y18: https://chipandco.com/summer-olympics-merchandise-disneyland-paris-570975/ | Z18: secondary | AA18: https://wdwnt.com/2024/07/2024-summer-olympics-merchandise-disney-paris/ | AB18: 2 | AG18: dlp/2024/summer-games-2024-gold-medal-mickey
A19: PHS-0018 | B19: Ratatouille pins (July 2024) | C19: Disneyland Paris | E19: 2024-07-10 | F19: 2024 | R19: 1 | S19: =IF(Q19="","",MAX(Q19-R19,0)) | T19: =IF(Q19="","",MIN(R19/Q19,1)) | U19: Chez Remy | W19: evidenced | X19: Low | Y19: https://www.mousesteps.com/2024/06/28/disneyland-paris-pin-release-schedule-for-july-2024-includes-aristocats-ratatouille-pins/ | Z19: secondary | AB19: 1 | AG19: dlp/2024/ratatouille-july-2024
A20: PHS-0019 | B20: March Hare LE 700 (July 2024) | C20: Disneyland Paris | E20: 2024-07-20 | F20: 2024 | L20: limited edition | M20: 700 | Q20: 1 | R20: 1 | S20: =IF(Q20="","",MAX(Q20-R20,0)) | T20: =IF(Q20="","",MIN(R20/Q20,1)) | U20: March Hare | W20: evidenced | X20: Low | Y20: https://www.mousesteps.com/2024/06/28/disneyland-paris-pin-release-schedule-for-july-2024-includes-aristocats-ratatouille-pins/ | Z20: secondary | AB20: 1 | AG20: dlp/2024/march-hare-le-700-july-2024
A21: PHS-0020 | B21: Beauty and the Beast pins and lanyard (August 10) | C21: Disneyland Paris | E21: 2024-08-10 | F21: 2024 | Q21: 4 | R21: 4 | S21: =IF(Q21="","",MAX(Q21-R21,0)) | T21: =IF(Q21="","",MIN(R21/Q21,1)) | U21: Belle; Cogsworth; Lumiere; Chip; Mrs. Potts | W21: evidenced | X21: Low | Y21: https://www.mousesteps.com/2024/07/29/disneyland-paris-august-2024-pins-feature-stitch-beauty-and-the-beast-and-more/ | Z21: secondary | AB21: 1 | AG21: dlp/2024/beauty-and-the-beast-august-2024
A22: PHS-0021 | B22: Characters with balloons (August 17) | C22: Disneyland Paris | E22: 2024-08-17 | F22: 2024 | R22: 4 | S22: =IF(Q22="","",MAX(Q22-R22,0)) | T22: =IF(Q22="","",MIN(R22/Q22,1)) | U22: Chip; Dale; Olaf; Pascal; Stitch | W22: evidenced | X22: Low | Y22: https://disneypinsblog.com/product/pascal-balloon-series-disneyland-paris-pin/ | Z22: secondary | AA22: https://www.mousesteps.com/2024/07/29/disneyland-paris-august-2024-pins-feature-stitch-beauty-and-the-beast-and-more/ | AB22: 2 | AG22: dlp/2024/balloons-august-2024
A23: PHS-0022 | B23: Pin Trading Time August 2024 surprise pins (The Emperor's New Groove) | C23: Disneyland Paris | E23: 2024-08-30 | F23: 2024 | L23: limited edition | M23: 400 | R23: 1 | S23: =IF(Q23="","",MAX(Q23-R23,0)) | T23: =IF(Q23="","",MIN(R23/Q23,1)) | U23: Kuzco | W23: evidenced | X23: Low | Y23: https://disneypinsblog.com/blogs/news/disneyland-paris-august-2024-pin-releases | Z23: secondary | AA23: https://disneypinsblog.com/blogs/news/disneyland-paris-august-2024-pin-trading-time-event-pin-releases | AB23: 3 | AG23: dlp/2024/pin-trading-time-august-2024-emperors-new-groove
A24: PHS-0023 | B24: Pin Trading Time August 2024 refresher pin (Miguel) | C24: Disneyland Paris | E24: 2024-08-30 | F24: 2024 | Q24: 1 | R24: 1 | S24: =IF(Q24="","",MAX(Q24-R24,0)) | T24: =IF(Q24="","",MIN(R24/Q24,1)) | U24: Miguel | W24: evidenced | X24: Low | Y24: https://disneypinsblog.com/blogs/news/disneyland-paris-august-2024-pin-trading-time-event-pin-releases | Z24: secondary | AB24: 1 | AG24: dlp/2024/pin-trading-time-august-2024-miguel-refresher
A25: PHS-0024 | B25: Halloween 2024 pins (Disneyland Paris) | C25: Disneyland Paris | E25: 2024-09 | F25: 2024 | L25: limited edition | R25: 5 | S25: =IF(Q25="","",MAX(Q25-R25,0)) | T25: =IF(Q25="","",MIN(R25/Q25,1)) | U25: Chip; Dale; Lucifer; Mickey Mouse; Pascal; Stitch | W25: evidenced | X25: Low | Y25: https://disneypinsblog.com/disneyland-paris-october-2024-pin-releases/ | Z25: secondary | AA25: https://medium.com/@kevin_24111/disneyland-paris-september-2024-pin-release-preview-sheet-schedule-1139688c519e | AB25: 3 | AG25: dlp/2024/halloween-2024
A26: PHS-0025 | B26: LE 700 Mickey; Minnie with Daisy (September 14) | C26: Disneyland Paris | E26: 2024-09-14 | F26: 2024 | L26: limited edition | M26: 700 | R26: 2 | S26: =IF(Q26="","",MAX(Q26-R26,0)) | T26: =IF(Q26="","",MIN(R26/Q26,1)) | U26: Mickey Mouse; Daisy Duck; Minnie Mouse | W26: evidenced (held) | X26: Low | Y26: https://www.mousesteps.com/2024/08/29/disneyland-paris-pin-release-schedule-for-september-2024-revealed/ | Z26: secondary | AB26: 1 | AG26: dlp/2024/le-700-mickey-minnie-daisy-september-2024
A27: PHS-0026 | B27: Tinker Bell Autumn LE 700 | C27: Disneyland Paris | E27: 2024-09-21 | F27: 2024 | L27: limited edition | M27: 700 | Q27: 1 | R27: 1 | S27: =IF(Q27="","",MAX(Q27-R27,0)) | T27: =IF(Q27="","",MIN(R27/Q27,1)) | U27: Tinker Bell | W27: evidenced | X27: Low | Y27: https://medium.com/@disney_mouseketeer/disneyland-paris-september-2024-pin-release-preview-sheet-schedule-1139688c519e | Z27: secondary | AA27: https://medium.com/@kevin_24111/disneyland-paris-september-2024-pin-release-preview-sheet-schedule-1139688c519e | AB27: 2 | AG27: dlp/2024/tinker-bell-autumn-le-700
A28: PHS-0027 | B28: Gaston and Belle LE (November 2) | C28: Disneyland Paris | E28: 2024-11-02 | F28: 2024 | L28: limited edition | R28: 1 | S28: =IF(Q28="","",MAX(Q28-R28,0)) | T28: =IF(Q28="","",MIN(R28/Q28,1)) | U28: Belle; Gaston | W28: evidenced | X28: Low | Y28: https://disneypinsblog.com/disneyland-paris-november-2024-pin-releases/ | Z28: secondary | AA28: https://www.mousesteps.com/2024/10/30/disneyland-paris-november-2024-pin-release-schedule-revealed/ | AB28: 2 | AG28: dlp/2024/gaston-and-belle-le-november-2024
A29: PHS-0028 | B29: The Aristocats open edition pins (November 16) | C29: Disneyland Paris | E29: 2024-11-16 | F29: 2024 | L29: open edition | R29: 4 | S29: =IF(Q29="","",MAX(Q29-R29,0)) | T29: =IF(Q29="","",MIN(R29/Q29,1)) | U29: Berlioz; Toulouse; Duchess; Marie; Thomas O'Malley | W29: evidenced | X29: Low | Y29: http://pixiedustdlp.com/2024/11/04/disneyland-paris-pin-trading-november-2024/ | Z29: secondary | AA29: https://www.mousesteps.com/2024/10/30/disneyland-paris-november-2024-pin-release-schedule-revealed/ | AB29: 2 | AG29: dlp/2024/aristocats-oe-november-2024
A30: PHS-0029 | B30: Happy Birthday cake pins (Mickey, Minnie, Donald, Daisy, Chip & Dale) | C30: Disneyland Paris | E30: 2024-11-16 | F30: 2024 | L30: limited edition | M30: 700 | N30: 18 | O30: EUR | Q30: 5 | R30: 5 | S30: =IF(Q30="","",MAX(Q30-R30,0)) | T30: =IF(Q30="","",MIN(R30/Q30,1)) | U30: Chip; Dale; Daisy Duck; Donald Duck; Mickey Mouse; Minnie Mouse | W30: evidenced | X30: Low | Y30: http://pixiedustdlp.com/2024/11/04/disneyland-paris-pin-trading-november-2024/ | Z30: secondary | AA30: https://disneypinsblog.com/disneyland-paris-november-2024-pin-releases/ | AB30: 4 | AG30: dlp/2024/happy-birthday-cakes-le-700
A31: PHS-0030 | B31: Ariel and Eric LE (November 23) | C31: Disneyland Paris | E31: 2024-11-23 | F31: 2024 | L31: limited edition | Q31: 1 | R31: 1 | S31: =IF(Q31="","",MAX(Q31-R31,0)) | T31: =IF(Q31="","",MIN(R31/Q31,1)) | U31: Ariel; Eric; Prince Eric | W31: evidenced | X31: Low | Y31: http://pixiedustdlp.com/2024/11/04/disneyland-paris-pin-trading-november-2024/ | Z31: secondary | AA31: https://www.mousesteps.com/2024/10/30/disneyland-paris-november-2024-pin-release-schedule-revealed/ | AB31: 2 | AG31: dlp/2024/ariel-and-eric-le-november-2024
A32: PHS-0031 | B32: Christmas 2024 Winnie the Pooh open edition pins | C32: Disneyland Paris | E32: 2024-11-23 | F32: 2024 | L32: open edition | Q32: 4 | R32: 4 | S32: =IF(Q32="","",MAX(Q32-R32,0)) | T32: =IF(Q32="","",MIN(R32/Q32,1)) | U32: Eeyore; Winnie the Pooh; Piglet; Tigger | W32: evidenced | X32: Low | Y32: http://pixiedustdlp.com/2024/11/04/disneyland-paris-pin-trading-november-2024/ | Z32: secondary | AA32: https://www.mousesteps.com/2024/10/30/disneyland-paris-november-2024-pin-release-schedule-revealed/ | AB32: 2 | AG32: dlp/2024/christmas-2024-pooh-oe
A33: PHS-0032 | B33: Mother Gothel limited edition pin | C33: Disneyland Paris | E33: 2025-01-08 | F33: 2025 | L33: limited edition | M33: 700 | Q33: 1 | R33: 1 | S33: =IF(Q33="","",MAX(Q33-R33,0)) | T33: =IF(Q33="","",MIN(R33/Q33,1)) | U33: Mother Gothel; Rapunzel | W33: evidenced | X33: Low | Y33: http://pixiedustdlp.com/2024/12/28/disneyland-paris-pin-trading-january-2025/ | Z33: secondary | AA33: https://disneypinsblog.com/disneyland-paris-january-2025-pin-releases/ | AB33: 3 | AG33: dlp/2025/mother-gothel-le-700
A34: PHS-0033 | B34: Pièces Jaunes Mickey pin (2025) | C34: Disneyland Paris | E34: 2025-01-08 | F34: 2025 | I34: charity collection single pin | Q34: 1 | R34: 1 | S34: =IF(Q34="","",MAX(Q34-R34,0)) | T34: =IF(Q34="","",MIN(R34/Q34,1)) | U34: Mickey Mouse | W34: evidenced | X34: Low | Y34: https://www.laughingplace.com/w/disney-merchandise/disneyland-paris-reveals-new-pieces-jaunes-collection/ | Z34: secondary | AA34: https://www.mousesteps.com/2024/12/27/disneyland-paris-january-2025-pins-revealed/ | AB34: 2 | AG34: dlp/2025/pieces-jaunes-mickey-2025
A35: PHS-0034 | B35: Mickey & Friends skiing pins | C35: Disneyland Paris | E35: 2025-01-11 | F35: 2025 | R35: 7 | S35: =IF(Q35="","",MAX(Q35-R35,0)) | T35: =IF(Q35="","",MIN(R35/Q35,1)) | U35: Chip 'n Dale; Daisy Duck; Donald Duck; Goofy; Mickey Mouse; Minnie Mouse; Pluto | W35: evidenced | X35: Low | Y35: http://pixiedustdlp.com/2024/12/28/disneyland-paris-pin-trading-january-2025/ | Z35: secondary | AA35: https://disneypinsblog.com/disneyland-paris-january-2025-pin-releases/ | AB35: 4 | AG35: dlp/2025/mickey-friends-skiing
A36: PHS-0035 | B36: Henry Ravenswood jumbo limited edition pin | C36: Disneyland Paris | E36: 2025-01-18 | F36: 2025 | I36: jumbo pin | L36: limited edition | M36: 700 | Q36: 1 | R36: 1 | S36: =IF(Q36="","",MAX(Q36-R36,0)) | T36: =IF(Q36="","",MIN(R36/Q36,1)) | U36: Henry Ravenswood | W36: evidenced | X36: Low | Y36: https://disneypinsblog.com/disneyland-paris-january-2025-pin-releases/ | Z36: secondary | AA36: https://www.mousesteps.com/2024/12/27/disneyland-paris-january-2025-pins-revealed/ | AB36: 2 | AG36: dlp/2025/henry-ravenswood-jumbo-le-700
A37: PHS-0036 | B37: Disneyland Hotel open edition pins | C37: Disneyland Paris | E37: 2025-01-24 | F37: 2025 | L37: open edition | Q37: 2 | R37: 2 | S37: =IF(Q37="","",MAX(Q37-R37,0)) | T37: =IF(Q37="","",MIN(R37/Q37,1)) | U37: Mickey Mouse; Minnie Mouse | W37: evidenced | X37: Low | Y37: http://pixiedustdlp.com/2024/12/28/disneyland-paris-pin-trading-january-2025/ | Z37: secondary | AA37: https://www.mousesteps.com/2024/12/27/disneyland-paris-january-2025-pins-revealed/ | AB37: 2 | AG37: dlp/2025/disneyland-hotel-oe-2025-01
A38: PHS-0037 | B38: Megara and Hercules limited edition pin | C38: Disneyland Paris | E38: 2025-01-25 | F38: 2025 | L38: limited edition | M38: 700 | Q38: 1 | R38: 1 | S38: =IF(Q38="","",MAX(Q38-R38,0)) | T38: =IF(Q38="","",MIN(R38/Q38,1)) | U38: Hercules; Megara | W38: evidenced | X38: Low | Y38: https://www.mousesteps.com/2024/12/27/disneyland-paris-january-2025-pins-revealed/ | Z38: secondary | AB38: 1 | AG38: dlp/2025/megara-hercules-le-700
A39: PHS-0038 | B39: Pin Trading Time January 2025 refresher pin (Cruella) | C39: Disneyland Paris | E39: 2025-01-31 | F39: 2025 | I39: event refresher pin | Q39: 1 | R39: 1 | S39: =IF(Q39="","",MAX(Q39-R39,0)) | T39: =IF(Q39="","",MIN(R39/Q39,1)) | U39: Cruella de Vil | W39: evidenced | X39: Low | Y39: https://disneypinsblog.com/blogs/news/disneyland-paris-january-2025-pin-trading-time-event-pin-releases | Z39: secondary | AB39: 1 | AG39: dlp/2025/pin-trading-time-2025-01-cheyenne-refresher-cruella
A40: PHS-0039 | B40: Lady Tremaine limited edition pin (Cinderella silhouette) | C40: Disneyland Paris | E40: 2025-02-08 | F40: 2025 | L40: limited edition | M40: 700 | Q40: 1 | R40: 1 | S40: =IF(Q40="","",MAX(Q40-R40,0)) | T40: =IF(Q40="","",MIN(R40/Q40,1)) | U40: Cinderella; Lady Tremaine | W40: evidenced | X40: Low | Y40: https://medium.com/@disney_mouseketeer/disneyland-paris-february-2025-pins-preview-sheet-schedule-77f6c793773a | Z40: secondary | AA40: https://www.mousesteps.com/2025/01/29/disneyland-paris-shares-february-2025-pin-releases/ | AB40: 2 | AG40: dlp/2025/lady-tremaine-le-700
...

Sheet Set_Members
A1: set_id | B1: slot | C1: characters | D1: pin_name | E1: variant (chaser/glitter/...) | F1: edition_size | G1: in_catalogue | H1: pinhunt_id | I1: image_status | J1: status | K1: confidence | L1: research_key
A2: PHS-0001 | B2: 1 | C2: Aladdin | D2: Aladdin – Disney Animated Cuties Mystery Pin Blind Pack – 2-Pc. | G2: possible | H2: PHUK-00000333 | I2: none | J2: candidate | K2: High | L2: animated-cuties/series-1/aladdin
A3: PHS-0001 | B3: 2 | C3: Alice | D3: Alice – Disney Animated Cuties Mystery Pin Blind Pack – 2-Pc. | G3: possible | H3: PHUK-00000331 | I3: none | J3: candidate | K3: High | L3: animated-cuties/series-1/alice
A4: PHS-0001 | B4: 3 | C4: Esmeralda; Esmerelda | D4: Esmeralda & Esmerelda – Disney Animated Cuties Mystery Pin Blind Pack – 2-Pc. | G4: possible | H4: PHUK-00000336 | I4: none | J4: candidate | K4: High | L4: animated-cuties/series-1/esmeralda
A5: PHS-0001 | B5: 4 | C5: Jim Hawkins | D5: Jim Hawkins – Disney Animated Cuties Mystery Pin Blind Pack – 2-Pc. | G5: possible | H5: PHUK-00000337 | I5: none | J5: candidate | K5: High | L5: animated-cuties/series-1/jim-hawkins
A6: PHS-0001 | B6: 5 | C6: Megara | D6: Megara – Disney Animated Cuties Mystery Pin Blind Pack – 2-Pc. | G6: possible | H6: PHUK-00000334 | I6: none | J6: candidate | K6: High | L6: animated-cuties/series-1/megara-meg
A7: PHS-0001 | B7: 6 | C7: Peter Pan | D7: Peter Pan – Disney Animated Cuties Mystery Pin Blind Pack – 2-Pc. | G7: possible | H7: PHUK-00000335 | I7: none | J7: candidate | K7: High | L7: animated-cuties/series-1/peter-pan
A8: PHS-0001 | B8: 7 | C8: Pinocchio | D8: Pinocchio – Disney Animated Cuties Mystery Pin Blind Pack – 2-Pc. | G8: possible | H8: PHUK-00000332 | I8: none | J8: candidate | K8: High | L8: animated-cuties/series-1/pinocchio
A9: PHS-0001 | B9: 8 | C9: Tinker Bell | D9: Tinker Bell – Disney Animated Cuties Mystery Pin Blind Pack – 2-Pc. | G9: possible | H9: PHUK-00000338 | I9: none | J9: candidate | K9: High | L9: animated-cuties/series-1/tinker-bell
A10: PHS-0002 | B10: 1 | C10: Ariel | D10: Ariel – Animated Cuties Series 2 Mystery Pin Set | G10: possible | I10: none | J10: candidate | K10: Low | L10: animated-cuties/series-2/ariel
A11: PHS-0002 | B11: 2 | C11: Flynn Rider | D11: Flynn Rider – Animated Cuties Series 2 Mystery Pin Set | G11: possible | I11: none | J11: candidate | K11: Low | L11: animated-cuties/series-2/flynn-rider
A12: PHS-0002 | B12: 3 | C12: Hercules | D12: Hercules – Animated Cuties Series 2 Mystery Pin Set | G12: possible | I12: none | J12: candidate | K12: Low | L12: animated-cuties/series-2/hercules
A13: PHS-0002 | B13: 4 | C13: Kuzco | D13: Kuzco – Animated Cuties Series 2 Mystery Pin Set | G13: possible | I13: none | J13: candidate | K13: Low | L13: animated-cuties/series-2/kuzco
A14: PHS-0002 | B14: 5 | C14: Li Shang | D14: Li Shang – Animated Cuties Series 2 Mystery Pin Set | G14: possible | I14: none | J14: candidate | K14: Low | L14: animated-cuties/series-2/li-shang
A15: PHS-0002 | B15: 6 | C15: Maleficent | D15: Maleficent – Animated Cuties Series 2 Mystery Pin Set | G15: possible | I15: none | J15: candidate | K15: Low | L15: animated-cuties/series-2/maleficent
A16: PHS-0002 | B16: 7 | C16: Sally | D16: Sally – Animated Cuties Series 2 Mystery Pin Set | G16: possible | I16: none | J16: candidate | K16: Low | L16: animated-cuties/series-2/sally
A17: PHS-0002 | B17: 8 | C17: Vanellope | D17: Vanellope – Animated Cuties Series 2 Mystery Pin Set | G17: possible | I17: none | J17: candidate | K17: Low | L17: animated-cuties/series-2/vanellope-von-schweetz
A18: PHS-0003 | B18: 1 | C18: Aladdin | F18: 3750 | G18: possible | I18: none | J18: candidate | K18: Medium | L18: brush-of-magic/limited-edition/aladdin
A19: PHS-0003 | B19: 2 | C19: Ariel | D19: Ariel Pin - The Little Mermaid - Limited Edition | F19: 3750 | G19: possible | I19: none | J19: candidate | K19: Low | L19: brush-of-magic/limited-edition/ariel
A20: PHS-0003 | B20: 3 | C20: Bambi | F20: 3750 | G20: possible | I20: none | J20: candidate | K20: Medium | L20: brush-of-magic/limited-edition/bambi
A21: PHS-0003 | B21: 4 | C21: Belle | F21: 3750 | G21: possible | I21: none | J21: candidate | K21: Medium | L21: brush-of-magic/limited-edition/belle
A22: PHS-0003 | B22: 5 | C22: Captain Hook | D22: Captain Hook Pin - Peter Pan - Limited Edition | F22: 3750 | G22: possible | I22: none | J22: candidate | K22: Low | L22: brush-of-magic/limited-edition/captain-hook
A23: PHS-0003 | B23: 6 | C23: Cinderella | D23: Cinderella Pin - Brush of Magic - Limited Edition | F23: 3750 | G23: possible | I23: none | J23: candidate | K23: High | L23: brush-of-magic/limited-edition/cinderella
A24: PHS-0003 | B24: 7 | C24: Darkwing Duck | F24: 3750 | G24: possible | I24: none | J24: candidate | K24: Medium | L24: brush-of-magic/limited-edition/darkwing-duck
A25: PHS-0003 | B25: 8 | C25: Donald Duck | D25: Donald Duck Pin - Brush of Magic - Limited Edition | F25: 3750 | G25: possible | I25: none | J25: candidate | K25: Medium | L25: brush-of-magic/limited-edition/donald-duck
A26: PHS-0003 | B26: 9 | C26: Dumbo | D26: Dumbo Limited Edition Pin, Brush of Magic | F26: 3750 | G26: possible | I26: none | J26: candidate | K26: High | L26: brush-of-magic/limited-edition/dumbo
A27: PHS-0003 | B27: 10 | C27: Gadget Hackwrench | D27: Gadget Pin - Chip 'n Dale's Rescue Rangers - Brush of Magic - Limited Edition | F27: 3750 | G27: possible | I27: none | J27: candidate | K27: Medium | L27: brush-of-magic/limited-edition/gadget-hackwrench
A28: PHS-0003 | B28: 11 | C28: Genie | D28: Genie Pin - Aladdin - Brush of Magic - Limited Edition | F28: 3750 | G28: possible | I28: none | J28: candidate | K28: Medium | L28: brush-of-magic/limited-edition/genie
A29: PHS-0003 | B29: 12 | C29: Grumpy | F29: 3750 | G29: possible | I29: none | J29: candidate | K29: Medium | L29: brush-of-magic/limited-edition/grumpy
A30: PHS-0003 | B30: 13 | C30: Hades | D30: Hades Pin - Hercules - Brush of Magic - Limited Edition | F30: 3750 | G30: possible | I30: none | J30: candidate | K30: Medium | L30: brush-of-magic/limited-edition/hades
A31: PHS-0003 | B31: 14 | C31: Hercules | D31: US: Hercules Pin - Brush of Magic - Limited Edition | Asia: Hercules Limited Edition Pin, Brush of Magic | F31: 3750 | G31: possible | I31: none | J31: candidate | K31: High | L31: brush-of-magic/limited-edition/hercules
A32: PHS-0003 | B32: 15 | C32: Maleficent | D32: Maleficent Limited Edition Pin, Sleeping Beauty, Brush of Magic | F32: 2250 | G32: possible | I32: none | J32: candidate | K32: High | L32: brush-of-magic/limited-edition/maleficent
A33: PHS-0003 | B33: 16 | C33: Marie | D33: Marie Limited Edition Pin, The Aristocats, Brush of Magic | F33: 3750 | G33: possible | I33: none | J33: candidate | K33: High | L33: brush-of-magic/limited-edition/marie
A34: PHS-0003 | B34: 17 | C34: Mickey Mouse | D34: Mickey Mouse on Animator's Desk Jumbo Pin - Brush of Magic - 2-Pc. - Limited Edition | F34: 3749 | G34: possible | I34: none | J34: candidate | K34: Medium | L34: brush-of-magic/limited-edition/mickey-animators-desk-jumbo
A35: PHS-0003 | B35: 18 | C35: Sorcerer Mickey | D35: Sorcerer Mickey Mouse Limited Edition Pin, Fantasia, Brush of Magic | F35: 2250 | G35: possible | I35: none | J35: candidate | K35: High | L35: brush-of-magic/limited-edition/mickey-mouse-sorcerer
A36: PHS-0004 | B36: 1 | C36: Cheshire Cat | D36: Cheshire Cat – US: Disney Brush of Magic Mystery Pin Blind Pack Series 1 - 2-Pc. - Limited Release | UK: Disney Brush of Magic Limited Release Mystery Pin Set | G36: possible | H36: PHUK-00000634 | I36: none | J36: candidate | K36: High | L36: brush-of-magic/mystery-series-1/cheshire-cat
A37: PHS-0004 | B37: 2 | C37: Dopey | D37: Dopey – US: Disney Brush of Magic Mystery Pin Blind Pack Series 1 - 2-Pc. - Limited Release | UK: Disney Brush of Magic Limited Release Mystery Pin Set | G37: possible | H37: PHUK-00000625 | I37: none | J37: candidate | K37: High | L37: brush-of-magic/mystery-series-1/dopey
A38: PHS-0004 | B38: 3 | C38: Goofy | D38: Goofy – US: Disney Brush of Magic Mystery Pin Blind Pack Series 1 - 2-Pc. - Limited Release | UK: Disney Brush of Magic Limited Release Mystery Pin Set | G38: possible | H38: PHUK-00000633 | I38: none | J38: candidate | K38: High | L38: brush-of-magic/mystery-series-1/goofy
A39: PHS-0004 | B39: 4 | C39: Oswald | D39: Disney Brush of Magic Mystery Pin Set Series 1 - Oswald the Lucky Rabbit | G39: possible | H39: PHUK-00000631 | I39: none | J39: candidate | K39: High | L39: brush-of-magic/mystery-series-1/oswald-the-lucky-rabbit
A40: PHS-0004 | B40: 5 | C40: Peter Pan | D40: Peter Pan – US: Disney Brush of Magic Mystery Pin Blind Pack Series 1 - 2-Pc. - Limited Release | UK: Disney Brush of Magic Limited Release Mystery Pin Set | G40: possible | H40: PHUK-00000627 | I40: none | J40: candidate | K40: High | L40: brush-of-magic/mystery-series-1/peter-pan
...

Sheet Evidence
A1: set_id | B1: source_url | C1: publisher | D1: source_class | E1: accessed_via | F1: fields_confirmed | G1: checked_by | H1: checked_at
A2: PHS-0001 | B2: https://www.disneystore.asia/my/disney-animated-cuties-mystery-2-piece-pin-blind-pack-438030755384.html | C2: disneystore.asia | D2: official | E2: search snippet / page
A3: PHS-0001 | B3: https://www.disneystore.com/disney-animated-cuties-mystery-pin-blind-pack-2-pc.-438030741301.html | C3: disneystore.com | D3: official | E3: search snippet / page
A4: PHS-0001 | B4: https://www.disneystore.eu/disney-animated-cuties-mystery-pin-set-438030755384.html | C4: disneystore.eu | D4: official | E4: search snippet / page
A5: PHS-0001 | B5: https://disneymouseketeer.com/disney-animated-cuties-mystery-pin-set-at-disney-store-disney-parks/ | C5: disneymouseketeer.com | D5: secondary | E5: search snippet / page
A6: PHS-0001 | B6: https://disneypinsblog.com/blogs/news/animated-cuties-mystery-pin-set-at-disney-parks | C6: disneypinsblog.com | D6: secondary | E6: search snippet / page
A7: PHS-0001 | B7: https://wdwnt.com/2026/01/animated-cuties-mystery-pin-box/ | C7: wdwnt.com | D7: secondary | E7: search snippet / page
A8: PHS-0002 | B8: https://disneypinsblog.com/blogs/news/animated-cuties-series-2-mystery-pin-set-at-disney-parks | C8: disneypinsblog.com | D8: secondary | E8: search snippet / page
A9: PHS-0002 | B9: https://www.threads.com/@disneypinsblog/post/DeS8m9FjKzi/new-animated-cuties-series-mystery-pin-set-at-disney-parks-open-edition-and-the/ | C9: threads.com | D9: secondary | E9: search snippet / page
A10: PHS-0003 | B10: https://www.disneystore.asia/hercules-limited-edition-pin-brush-of-magic-438010541600.html | C10: disneystore.asia | D10: official | E10: search snippet / page
A11: PHS-0003 | B11: https://www.disneystore.asia/maleficent-limited-edition-pin-sleeping-beauty-brush-of-magic-438010541112.html | C11: disneystore.asia | D11: official | E11: search snippet / page
A12: PHS-0003 | B12: https://www.disneystore.asia/sorcerer-mickey-mouse-limited-edition-pin-fantasia%C2%A0brush-of-magic-438010540955.html | C12: disneystore.asia | D12: official | E12: search snippet / page
A13: PHS-0003 | B13: https://www.disneystore.co.uk/marie-limited-edition-pin-the-aristocats-brush-of-magic-438010541945.html | C13: disneystore.co.uk | D13: official | E13: search snippet / page
... A765: PHS-0296 | B765: https://disneypinsblog.com/new-disney-pins-july-2026-week-1/ | C765: disneypinsblog.com | D765: secondary | E765: search snippet / page

Sheet Coverage
A1: sets by line x year (from Sets) | B1: 2020 | C1: 2021 | D1: 2022 | E1: 2023 | F1: 2024 | G1: 2025 | H1: 2026 | I1: total
A2: Disneyland Paris | B2: =COUNTIFS(Sets!$C:$C,$A2,Sets!$F:$F,2020) | C2: =COUNTIFS(Sets!$C:$C,$A2,Sets!$F:$F,2021) | D2: =COUNTIFS(Sets!$C:$C,$A2,Sets!$F:$F,2022) | E2: =COUNTIFS(Sets!$C:$C,$A2,Sets!$F:$F,2023) | F2: =COUNTIFS(Sets!$C:$C,$A2,Sets!$F:$F,2024) | G2: =COUNTIFS(Sets!$C:$C,$A2,Sets!$F:$F,2025) | H2: =COUNTIFS(Sets!$C:$C,$A2,Sets!$F:$F,2026) | I2: =SUM(B2:H2)
A3: Disney Store UK | B3: =COUNTIFS(Sets!$C:$C,$A3,Sets!$F:$F,2020) | C3: =COUNTIFS(Sets!$C:$C,$A3,Sets!$F:$F,2021) | D3: =COUNTIFS(Sets!$C:$C,$A3,Sets!$F:$F,2022) | E3: =COUNTIFS(Sets!$C:$C,$A3,Sets!$F:$F,2023) | F3: =COUNTIFS(Sets!$C:$C,$A3,Sets!$F:$F,2024) | G3: =COUNTIFS(Sets!$C:$C,$A3,Sets!$F:$F,2025) | H3: =COUNTIFS(Sets!$C:$C,$A3,Sets!$F:$F,2026) | I3: =SUM(B3:H3)
A4: Walt Disney World | B4: =COUNTIFS(Sets!$C:$C,$A4,Sets!$F:$F,2020) | C4: =COUNTIFS(Sets!$C:$C,$A4,Sets!$F:$F,2021) | D4: =COUNTIFS(Sets!$C:$C,$A4,Sets!$F:$F,2022) | E4: =COUNTIFS(Sets!$C:$C,$A4,Sets!$F:$F,2023) | F4: =COUNTIFS(Sets!$C:$C,$A4,Sets!$F:$F,2024) | G4: =COUNTIFS(Sets!$C:$C,$A4,Sets!$F:$F,2025) | H4: =COUNTIFS(Sets!$C:$C,$A4,Sets!$F:$F,2026) | I4: =SUM(B4:H4)
A5: Disneyland Resort | B5: =COUNTIFS(Sets!$C:$C,$A5,Sets!$F:$F,2020) | C5: =COUNTIFS(Sets!$C:$C,$A5,Sets!$F:$F,2021) | D5: =COUNTIFS(Sets!$C:$C,$A5,Sets!$F:$F,2022) | E5: =COUNTIFS(Sets!$C:$C,$A5,Sets!$F:$F,2023) | F5: =COUNTIFS(Sets!$C:$C,$A5,Sets!$F:$F,2024) | G5: =COUNTIFS(Sets!$C:$C,$A5,Sets!$F:$F,2025) | H5: =COUNTIFS(Sets!$C:$C,$A5,Sets!$F:$F,2026) | I5: =SUM(B5:H5)
A6: Brush Of Magic | B6: =COUNTIFS(Sets!$C:$C,$A6,Sets!$F:$F,2020) | C6: =COUNTIFS(Sets!$C:$C,$A6,Sets!$F:$F,2021) | D6: =COUNTIFS(Sets!$C:$C,$A6,Sets!$F:$F,2022) | E6: =COUNTIFS(Sets!$C:$C,$A6,Sets!$F:$F,2023) | F6: =COUNTIFS(Sets!$C:$C,$A6,Sets!$F:$F,2024) | G6: =COUNTIFS(Sets!$C:$C,$A6,Sets!$F:$F,2025) | H6: =COUNTIFS(Sets!$C:$C,$A6,Sets!$F:$F,2026) | I6: =SUM(B6:H6)
A7: Animated Cuties | B7: =COUNTIFS(Sets!$C:$C,$A7,Sets!$F:$F,2020) | C7: =COUNTIFS(Sets!$C:$C,$A7,Sets!$F:$F,2021) | D7: =COUNTIFS(Sets!$C:$C,$A7,Sets!$F:$F,2022) | E7: =COUNTIFS(Sets!$C:$C,$A7,Sets!$F:$F,2023) | F7: =COUNTIFS(Sets!$C:$C,$A7,Sets!$F:$F,2024) | G7: =COUNTIFS(Sets!$C:$C,$A7,Sets!$F:$F,2025) | H7: =COUNTIFS(Sets!$C:$C,$A7,Sets!$F:$F,2026) | I7: =SUM(B7:H7)
A9: pins found by line x year
A10: Disneyland Paris | B10: =SUMIFS(Sets!$R:$R,Sets!$C:$C,$A10,Sets!$F:$F,2020) | C10: =SUMIFS(Sets!$R:$R,Sets!$C:$C,$A10,Sets!$F:$F,2021) | D10: =SUMIFS(Sets!$R:$R,Sets!$C:$C,$A10,Sets!$F:$F,2022) | E10: =SUMIFS(Sets!$R:$R,Sets!$C:$C,$A10,Sets!$F:$F,2023) | F10: =SUMIFS(Sets!$R:$R,Sets!$C:$C,$A10,Sets!$F:$F,2024) | G10: =SUMIFS(Sets!$R:$R,Sets!$C:$C,$A10,Sets!$F:$F,2025) | H10: =SUMIFS(Sets!$R:$R,Sets!$C:$C,$A10,Sets!$F:$F,2026)
A11: Disney Store UK | B11: =SUMIFS(Sets!$R:$R,Sets!$C:$C,$A11,Sets!$F:$F,2020) | C11: =SUMIFS(Sets!$R:$R,Sets!$C:$C,$A11,Sets!$F:$F,2021) | D11: =SUMIFS(Sets!$R:$R,Sets!$C:$C,$A11,Sets!$F:$F,2022) | E11: =SUMIFS(Sets!$R:$R,Sets!$C:$C,$A11,Sets!$F:$F,2023) | F11: =SUMIFS(Sets!$R:$R,Sets!$C:$C,$A11,Sets!$F:$F,2024) | G11: =SUMIFS(Sets!$R:$R,Sets!$C:$C,$A11,Sets!$F:$F,2025) | H11: =SUMIFS(Sets!$R:$R,Sets!$C:$C,$A11,Sets!$F:$F,2026)
A12: Walt Disney World | B12: =SUMIFS(Sets!$R:$R,Sets!$C:$C,$A12,Sets!$F:$F,2020) | C12: =SUMIFS(Sets!$R:$R,Sets!$C:$C,$A12,Sets!$F:$F,2021) | D12: =SUMIFS(Sets!$R:$R,Sets!$C:$C,$A12,Sets!$F:$F,2022) | E12: =SUMIFS(Sets!$R:$R,Sets!$C:$C,$A12,Sets!$F:$F,2023) | F12: =SUMIFS(Sets!$R:$R,Sets!$C:$C,$A12,Sets!$F:$F,2024) | G12: =SUMIFS(Sets!$R:$R,Sets!$C:$C,$A12,Sets!$F:$F,2025) | H12: =SUMIFS(Sets!$R:$R,Sets!$C:$C,$A12,Sets!$F:$F,2026)
A13: Disneyland Resort | B13: =SUMIFS(Sets!$R:$R,Sets!$C:$C,$A13,Sets!$F:$F,2020) | C13: =SUMIFS(Sets!$R:$R,Sets!$C:$C,$A13,Sets!$F:$F,2021) | D13: =SUMIFS(Sets!$R:$R,Sets!$C:$C,$A13,Sets!$F:$F,2022) | E13: =SUMIFS(Sets!$R:$R,Sets!$C:$C,$A13,Sets!$F:$F,2023) | F13: =SUMIFS(Sets!$R:$R,Sets!$C:$C,$A13,Sets!$F:$F,2024) | G13: =SUMIFS(Sets!$R:$R,Sets!$C:$C,$A13,Sets!$F:$F,2025) | H13: =SUMIFS(Sets!$R:$R,Sets!$C:$C,$A13,Sets!$F:$F,2026)
A14: Brush Of Magic | B14: =SUMIFS(Sets!$R:$R,Sets!$C:$C,$A14,Sets!$F:$F,2020) | C14: =SUMIFS(Sets!$R:$R,Sets!$C:$C,$A14,Sets!$F:$F,2021) | D14: =SUMIFS(Sets!$R:$R,Sets!$C:$C,$A14,Sets!$F:$F,2022) | E14: =SUMIFS(Sets!$R:$R,Sets!$C:$C,$A14,Sets!$F:$F,2023) | F14: =SUMIFS(Sets!$R:$R,Sets!$C:$C,$A14,Sets!$F:$F,2024) | G14: =SUMIFS(Sets!$R:$R,Sets!$C:$C,$A14,Sets!$F:$F,2025) | H14: =SUMIFS(Sets!$R:$R,Sets!$C:$C,$A14,Sets!$F:$F,2026)
A15: Animated Cuties | B15: =SUMIFS(Sets!$R:$R,Sets!$C:$C,$A15,Sets!$F:$F,2020) | C15: =SUMIFS(Sets!$R:$R,Sets!$C:$C,$A15,Sets!$F:$F,2021) | D15: =SUMIFS(Sets!$R:$R,Sets!$C:$C,$A15,Sets!$F:$F,2022) | E15: =SUMIFS(Sets!$R:$R,Sets!$C:$C,$A15,Sets!$F:$F,2023) | F15: =SUMIFS(Sets!$R:$R,Sets!$C:$C,$A15,Sets!$F:$F,2024) | G15: =SUMIFS(Sets!$R:$R,Sets!$C:$C,$A15,Sets!$F:$F,2025) | H15: =SUMIFS(Sets!$R:$R,Sets!$C:$C,$A15,Sets!$F:$F,2026)

Sheet Lookups
A1: line / origin | B1: format | C1: status | D1: source_class | E1: image_status
A2: Disneyland Paris | B2: single pin | C2: discovered | D2: official | E2: none
A3: Disney Store UK | B3: boxed set | C3: evidenced | D3: licensee | E3: own photo
A4: Disney Store EU | B4: booster | C4: evidenced (held) | D4: news | E4: contributor photo (licensed)
A5: shopDisney US | B5: mystery box/pouch | C5: checked | D5: fan | E5: official link only (no copy)
A6: Walt Disney World | B6: starter set | C6: approved | D6: fan database (discovery only) | E6: licensed feed image
A7: Disneyland Resort | B7: lanyard set | C7: imported | D7: own photo | E7: do not use
A8: Tokyo Disney Resort | B8: jumbo | C8: rejected
A9: Shanghai Disney Resort | B9: event set
A10: Hong Kong Disneyland | B10: advent calendar
A11: Loungefly
A12: Artland
A13: Other licensee
